Workbook
Name diet_items: AOM_diets!$M:$Q

Sheet bibliography

Sheet era_fields_v1
A1: Field.Name | B1: Data.Type | C1: Description | D1: Example
A2: Index | B2: Numeric | C2: A unique number identifiying an single observation (i.e. row) in ERA.
A3: Code | B3: Character | C3: Each paper is assigned a unique code that can be used to identify the source of the data in the database. The code consists of your initials (first and last name) and a sequential four-digit number that begins with 0000 and goes up 1 with each paper entered. | D3: TR0343
D4: NN1002
A5: Author | B5: Character | C5: The name of the first author, last name comes first with no punctuation. Use all initials given and do not include spaces between initials. | D5: Bucagu C
D6: Yamoah CF
A7: Date | B7: Positive Integer | C7: The year of publication.
A8: Journal | B8: Character | C8: Abbreviation of the journal name. We use WoS abbreviations that can be found here: https://images.webofknowledge.com/images/help/WOS/A_abrvjt.html | D8: Soil & Tillage Research = STR
C9: This field will autofill using the data in the Levels tab matching to the user selected journal name. | D9: Journal of Plant Nutrition = JPN
A10: DOI | B10: Character | C10: DOI (or url if no DOI available) of article. DOI = Digital Object Identifier.
A11: Elevation | B11: Integer | C11: The elevation in meters (m). Provide the mid-point if a range is given. | D11: 875
A12: Country | B12: Character | C12: Country Name | D12: Kenya
D13: Ivory Coast
A14: ISO.3166-1.alpha-3 | B14: Character | C14: Standardized country name using ISO.3166-1.alpha-3. This field should be auto filled using the country selected and data in the Levels Tab, | D14: KEN
D15: CIV
A16: Site.Type | B16: Character | C16: One of the following: Farm, Station, Greenhouse, Survey, or Lab. Farm research is conducted in a farmer’s field and can be managed by the farmer or researcher. Station research is conducted in a controlled setting of research station, university or school. Survey research is conducted via interviews that yields quantitative data based on testimonial. Greenhouse is conducted in a greenhouse and is only relevant for studies of greenhouse gas emissions data. Lab studies can include fisheries feeding trials conducted at a small scale in university research labs. | D16: Farm
A17: Site.ID | B17: Character | C17: Free text name to identify the site. Include institution/station name and location or village/town in county/district, but not the country. | D17: Chitedze ARS, Lilongwe
D18: IITA, Ibadan
A19: MAT | B19: Numeric | C19: Reported mean annual temperature in degrees C. If a range is given, average the values and enter the average. If mean highs and lows are given, they can be averaged to estimate the mean annual temperature.
A20: MAP | B20: Numeric | C20: Mean annual precipitation (mm) for the location. This should be a long-term average for more than 10 years of data.
A21: TAP | B21: Numeric | C21: Total annual precipitation (mm) for the location in the year corresponding to the outcome data
A22: MSP | B22: Numeric | C22: Mean seasonal precipitation (mm) for the location in the season corresponding to the outcome data. This should be a long-term average from more than 10 years of data.
A23: TSP | B23: Numeric | C23: Total seasonal precipitation (mm) for the location in the season corresponding to the outcome data
A24: Soil.Type | B24: Character | C24: List the given soil classification/name in lowercase letters. If more than one soil type is given (within the same taxonomic system) enter both separated by a period ‘.’ | D24: ferric lixisol
D25: lixisol.plinthisol
A26: Soil.Classification | B26: Character | C26: List the taxonomic system used to classify the soil. Choose from {FAO, USDA, other}. | D26: FAO
A27: Soil.Texture | B27: Character | C27: List the soil texture provided in the text or in tables in lowercase letters. If no texture is named, but % of sand, silt and clay are given, use the soil texture triangle to estimate soil texture (https://www.nrcs.usda.gov/wps/portal/nrcs/detail/soils/survey/?cid=nrcs142p2_054167). | D27: sandy loam
D28: clay
A29: SOC | B29: Numeric | C29: Soil organic carbon. If multiple soil depths are reported, use 0-20 cm, or the closest reported value. Do NOT use soil organic matter (SOM) or total carbon (TSC) measurements here. | D29: 3.4
D30: 0.54
A31: SOC.Unit | B31: Character | C31: Units provided for soil organic carbon. Usually either g/kg or % (also can be density kg/m3 or stocks t/ha) | D31: %
A32: SOC.Depth | B32: Character | C32: Concatenate min (top) and max (bottom) depths user entered with a ""-"", e.g. 0-10. | D32: 10
D33: 20
A34: Soil.pH | B34: Positive Integer | C34: Soil pH value derived during site characterization. If multiple methods for pH are given, report the water (H2O) method. | D34: 5.9
A35: Soil.pH.Method | B35: Character | C35: Method used to calculate soil pH. | D35: CaCl2
A36: Plant.Start | B36: Date | C36: Starting of planting period (dd.mm.yyyy) | D36: 01.12.2015
A37: Plant.End | B37: Date | C37: End of planting period (dd.mm.yyyy) | D37: 10.12.2015
A38: Harvest.Start | B38: Date | C38: Starting of harvest period (dd.mm.yyyy) | D38: 04.04.2016
A39: Harvest.End | B39: Date | C39: End of harvest period (dd.mm.yyyy) | D39: 05.04.2016
A40: Rep | B40: Positive Integer | C40: The number of replicates for the treatments. If the number varies between treatments, use the lowest number. If no number is given, leave blank. | D40: 4
...

Sheet era_fields_v2
A1: Table | B1: Table_Description | C1: Field | D1: majestic_hippo_2020 | E1: skinny_cow_2022 | F1: industrious_elephant_2023 | G1: courageous_camel_2024 | H1: key_type | I1: source_table | J1: lookup_table | K1: Calculated | L1: Display_Name | M1: Data_Type | N1: Field_Description | O1: Notes | P1: Values | Q1: Validation | R1: Required | S1: Ref_Source | T1: Ref_Name | U1: Ref_Link | V1: Ref_Match | W1: Ref_Notes | X1: Translation source | Y1: Spanish Translation | Z1: Ref2_DataScribe | AA1: Ref2_Source | AB1: Ref2_Name | AC1: Ref2_Link | AD1: Ref2_Match | AE1: Ref2_Notes | AF1: Other_Links
A2: Pub.Out | B2: This table captures bibliographic information. Each publication is assigned a unique code in the B.Code field that acts a key field in all other extraction template tables. | C2: B.Code | D2: TRUE | E2: TRUE | F2: TRUE | G2: TRUE | H2: p | K2: Yes | L2: ERA Publication Code | M2: Character | N2: A unique code that identifies an extracted publication in the ERA dataset. This code is present in all the tables of era extraction data models. | P2: concatenation of unique userID and a number | Q2: NA | R2: NA | S2: NA | T2: NA | U2: NA | V2: NA | W2: NA | Z2: NA | AA2: NA | AB2: NA | AC2: NA | AD2: NA | AE2: NA | AF2: NA
A3: Pub.Out | B3: =B2 -> This table captures bibliographic information. Each publication is assigned a unique code in the B.Code field that acts a key field in all other extraction template tables. | C3: B.Author.Last | D3: TRUE | E3: TRUE | F3: TRUE | G3: TRUE | K3: No | L3: Author Last Name | M3: Character | N3: Publication first author's surname. | P3: Free Text | Q3: NA | R3: NA
A4: Pub.Out | B4: =B3 -> This table captures bibliographic information. Each publication is assigned a unique code in the B.Code field that acts a key field in all other extraction template tables. | C4: B.Date | D4: TRUE | E4: TRUE | F4: TRUE | G4: TRUE | K4: No | L4: Year Published | M4: Integer (YYYY) | N4: The year of publication. | P4: NA | Q4: Integer >1950 & <=Present Year | R4: Yes
A5: Pub.Out | B5: =B4 -> This table captures bibliographic information. Each publication is assigned a unique code in the B.Code field that acts a key field in all other extraction template tables. | C5: B.Journal | D5: TRUE | E5: TRUE | F5: TRUE | G5: TRUE | K5: No | L5: Journal | M5: Character | N5: Name of journal this research is published in. | P5: SCiO should have some ideas how to populate this field | Q5: NA | R5: Yes
A6: Pub.Out | B6: =B5 -> This table captures bibliographic information. Each publication is assigned a unique code in the B.Code field that acts a key field in all other extraction template tables. | C6: B.DOI | D6: TRUE | E6: TRUE | F6: TRUE | G6: TRUE | K6: No | L6: DOI | M6: Character | N6: Digital object identifier (DOI) for the publication (e.g. 10.1080/03650340.2017.1411589). Do not include https://doi.org/ when entering this. Please strip the “https://doi.org/” when entering a doi . Correct = “10.1002/jrsm.1563”, Incorrect = “https://doi.org/10.1002/jrsm.1563”. If there is no DOI for a publication then report the https address of the article. | P6: Free Text | Q6: Strip out https:// | R6: One of B.Doi or B.Url required
A7: Pub.Out | B7: =B6 -> This table captures bibliographic information. Each publication is assigned a unique code in the B.Code field that acts a key field in all other extraction template tables. | C7: B.Url | D7: TRUE | E7: TRUE | F7: TRUE | G7: TRUE | K7: No | L7: Website | M7: Character | N7: For a publication with no DOI, please enter the full website address where it can be found. | O7: Has this field been merged with doi in the new data model | P7: Free Text | Q7: Should be a web address | R7: One of B.Doi or B.Url required
A8: Pub.Out | B8: =B7 -> This table captures bibliographic information. Each publication is assigned a unique code in the B.Code field that acts a key field in all other extraction template tables. | C8: B.Project | D8: TRUE | E8: TRUE | F8: TRUE | G8: TRUE | K8: No | L8: Project | M8: Character | N8: Name the project of the current extraction round | P8: Data extractions will relate to specific projects/budgets/modules this field will link to a table of projects that the user can define, or a user is assigned to a specific project and it autofills. | Q8: NA | R8: Yes
A9: Pub.Out | B9: =B8 -> This table captures bibliographic information. Each publication is assigned a unique code in the B.Code field that acts a key field in all other extraction template tables. | C9: B.Link1 | D9: TRUE | E9: TRUE | F9: TRUE | G9: TRUE | K9: No | L9: Linked Publication DOI/Website 1 | M9: Character | N9: Publications that are referenced in this publication that may present results from the same experiment. | P9: Free Text | Q9: Should be a web address or DOI | R9: No
A10: Pub.Out | B10: =B9 -> This table captures bibliographic information. Each publication is assigned a unique code in the B.Code field that acts a key field in all other extraction template tables. | C10: B.Link2 | D10: TRUE | E10: TRUE | F10: TRUE | G10: TRUE | K10: No | L10: Linked Publication DOI/Website 2 | M10: Character | N10: Publications that are referenced in this publication that may present results from the same experiment. | P10: Free Text | Q10: Should be a web address or DOI | R10: No
A11: Pub.Out | B11: =B10 -> This table captures bibliographic information. Each publication is assigned a unique code in the B.Code field that acts a key field in all other extraction template tables. | C11: B.Link3 | D11: TRUE | E11: TRUE | F11: TRUE | G11: TRUE | K11: No | L11: Linked Publication DOI/Website 3 | M11: Character | N11: Publications that are referenced in this publication that may present results from the same experiment. | P11: Free Text | Q11: Should be a web address or DOI | R11: No
A12: Pub.Out | B12: =B11 -> This table captures bibliographic information. Each publication is assigned a unique code in the B.Code field that acts a key field in all other extraction template tables. | C12: B.Link4 | D12: TRUE | E12: TRUE | F12: TRUE | G12: TRUE | K12: No | L12: Linked Publication DOI/Website 4 | M12: Character | N12: Publications that are referenced in this publication that may present results from the same experiment. | P12: Free Text | Q12: Should be a web address or DOI | R12: No
A13: Site.Out | B13: Here we record the geographic co-ordinates of where an experiment has taken place and the uncertainty associated with this. You can record multiple locations. For each site you can also capture general biophysical information about the site and the starting conditions that describe the soils of the site. | C13: Site.Type | D13: TRUE | E13: TRUE | F13: TRUE | G13: TRUE | K13: No | L13: What is the context of the experiment? | M13: Character | N13: This describes the nature of the field and who is managing it | P13: lookup_levels$Site.Type | Q13: NA | R13: Yes
A14: Site.Out | B14: Here we record the geographic co-ordinates of where an experiment has taken place and the uncertainty associated with this. You can record multiple locations. For each site you can also capture general biophysical information about the site and the starting conditions that describe the soils of the site. | C14: Country | D14: TRUE | E14: TRUE | F14: TRUE | G14: TRUE | K14: No | L14: Country | M14: Character | N14: Country where the study is performed | P14: Country$Countries | Q14: NA | R14: Yes
A15: Site.Out | B15: Here we record the geographic co-ordinates of where an experiment has taken place and the uncertainty associated with this. You can record multiple locations. For each site you can also capture general biophysical information about the site and the starting conditions that describe the soils of the site. | C15: Site.ID | D15: TRUE | E15: TRUE | F15: TRUE | G15: TRUE | H15: p | K15: No | L15: Site Name | M15: Character | N15: If you select a site name that already exists in ERA, the latitude and longitude fields will auto-populate. Please check the auto-generated co-ordinates against the ones reported in the publication and in GoogleMaps/Earth. If there is a mismatch you can overwrite the autogenerated values. | P15: Free Text/Can choose exisiting Site.ID for specified Country within the database or add a new one, perhaps the list should also be subset by Site experimental type. If co-ordinates are changed for the site we need to Flag this to check. | Q15: None | R15: Yes
A16: Site.Out | B16: Here we record the geographic co-ordinates of where an experiment has taken place and the uncertainty associated with this. You can record multiple locations. For each site you can also capture general biophysical information about the site and the starting conditions that describe the soils of the site. | C16: Site.Admin | D16: TRUE | E16: TRUE | F16: TRUE | G16: TRUE | K16: No | L16: How is the location reported? | M16: Character | N16: A qualitative measure of how accurate you think the location reporting is. If the study is at a research station, but we only know the location of the city where the station is, we record "City". If we know the exact location of the station record "Facility". | P16: lookup_levels$Site.Admin | Q16: NA | R16: Yes
A17: Site.Out | B17: Here we record the geographic co-ordinates of where an experiment has taken place and the uncertainty associated with this. You can record multiple locations. For each site you can also capture general biophysical information about the site and the starting conditions that describe the soils of the site. | C17: Site.Agg | D17: TRUE | E17: TRUE | F17: TRUE | G17: TRUE | K17: No | L17: Does the location contain sub-locations? | M17: Character | N17: State yes if a paper reports a general location which contains sub-locations that you do not know the co-ordinates of. For example a paper might state "we repeated the experiment on 10 farms in 5 villages in Busia county, Kenya" so we have a county location and know there are 5 village sub-locations in this county, we don't know where these villages are and results are reported averaged across all the farms and villages. If we know the location or names of the villages (e.g. results are reported per village) then we create one site per village and state "no" in this field. | P17: Yes, No | Q17: NA | R17: Yes
A18: Site.Out | B18: Here we record the geographic co-ordinates of where an experiment has taken place and the uncertainty associated with this. You can record multiple locations. For each site you can also capture general biophysical information about the site and the starting conditions that describe the soils of the site. | C18: ISO.3166.1.alpha.3 | D18: FALSE | E18: TRUE | F18: TRUE | G18: TRUE | K18: No | L18: Enter the Iso Code of the Country | M18: Character | N18: Three letters code for countries | O18: this is not in the excel but in the dataset in R | Q18: NA | R18: No
A19: Site.Out | B19: Here we record the geographic co-ordinates of where an experiment has taken place and the uncertainty associated with this. You can record multiple locations. For each site you can also capture general biophysical information about the site and the starting conditions that describe the soils of the site. | C19: Site.LatD | D19: TRUE | E19: TRUE | F19: TRUE | G19: TRUE | K19: No | L19: Latitude (Decimal Degrees) | M19: Numeric | N19: Longitude and latitude are geographic coordinates that specify the position of a point on the Earth's surface, with longitude measuring east-west position and latitude measuring north-south position | P19: NA | Q19: Should be within the country selected. | R19: Yes
A20: Site.Out | B20: Here we record the geographic co-ordinates of where an experiment has taken place and the uncertainty associated with this. You can record multiple locations. For each site you can also capture general biophysical information about the site and the starting conditions that describe the soils of the site. | C20: Site.Lat.Unc | D20: TRUE | E20: TRUE | F20: TRUE | G20: TRUE | K20: No | L20: Latitude Uncertainty (m) | M20: Numeric | N20: An important field used where a location is a region (e.g. a county or district polygon) which has a bounding box that is more rectangular than square (if square then just used the Uncertainty (Radius in m) field). Give the height of the region NAMITA IS THIS THE TOTAL HEIGHT OR HALF THE HEIGHT in meters? | P20: NA | Q20: Values <=10m are suspicious (this would be very tiny region or experiment) | R20: Yes if Site.Buffer.Manual is blank or Site.Lon.Unc is not blank
A21: Site.Out | B21: Here we record the geographic co-ordinates of where an experiment has taken place and the uncertainty associated with this. You can record multiple locations. For each site you can also capture general biophysical information about the site and the starting conditions that describe the soils of the site. | C21: Site.LonD | D21: TRUE | E21: TRUE | F21: TRUE | G21: TRUE | K21: No | L21: Longitude (Decimal Degrees) | M21: Numeric | N21: Longitude and latitude are geographic coordinates that specify the position of a point on the Earth's surface, with longitude measuring east-west position and latitude measuring north-south position | P21: NA | Q21: Should be within the country selected. | R21: Yes
A22: Site.Out | B22: Here we record the geographic co-ordinates of where an experiment has taken place and the uncertainty associated with this. You can record multiple locations. For each site you can also capture general biophysical information about the site and the starting conditions that describe the soils of the site. | C22: Site.Lon.Unc | D22: TRUE | E22: TRUE | F22: TRUE | G22: TRUE | K22: No | L22: Longitude Uncertainty (m) | M22: Numeric | N22: An important field used where a location is a region (e.g. a county or district polygon) which has a bounding box that is more rectangular than square (if square then just used the Uncertainty (Radius in m) field). Give the width of the region NAMITA IS THIS THE TOTAL HEIGHT OR HALF THE HEIGHT in meters? | Q22: Values <=10m are suspicious (this would be very tiny region or experiment) | R22: Yes if Site.Buffer.Manual is blank or Site.Lat.Unc is not blank
A23: Site.Out | B23: Here we record the geographic co-ordinates of where an experiment has taken place and the uncertainty associated with this. You can record multiple locations. For each site you can also capture general biophysical information about the site and the starting conditions that describe the soils of the site. | C23: Site.Buffer.Manual | D23: TRUE | E23: TRUE | F23: TRUE | G23: TRUE | K23: No | L23: Uncertainty (Radius in m) | M23: Numeric | N23: An important field used to indicate spatial uncertainty where a location is a point or a region (e.g. a county or district polygon) with a square bounding box. Give the radius of uncertainty in meter for the point or region (so the distance from the centre of the region or study plot to the edge). If the study site is a research station you take the centre of the research station to the edge of the station. | Q23: Values <=10m are suspicious (this would be very tiny region or experiment) | R23: Yes if Site.Lat.Unc & Site.Lon.Unc are not blank, not allowed to be filled if Site.Lat.Unc|Site.Lon.Unc are not blank.
A24: Site.Out | B24: Here we record the geographic co-ordinates of where an experiment has taken place and the uncertainty associated with this. You can record multiple locations. For each site you can also capture general biophysical information about the site and the starting conditions that describe the soils of the site. | C24: Site.Rain.Seasons | D24: TRUE | E24: TRUE | F24: TRUE | G24: TRUE | K24: No | L24: Number of Rainy Seasons | M24: Integer | N24: Number of rainy seasons | P24: 1,2,Year Round,Unspecified,NA | Q24: NA | R24: Yes
A25: Site.Out | B25: Here we record the geographic co-ordinates of where an experiment has taken place and the uncertainty associated with this. You can record multiple locations. For each site you can also capture general biophysical information about the site and the starting conditions that describe the soils of the site. | C25: Site.Start.S1 | D25: TRUE | E25: TRUE | F25: TRUE | G25: TRUE | K25: No | L25: Season1 Start | M25: Character | N25: start date of the first season | P25: lookup_levels$Site.Seasons | Q25: NA | R25: No
A26: Site.Out | B26: Here we record the geographic co-ordinates of where an experiment has taken place and the uncertainty associated with this. You can record multiple locations. For each site you can also capture general biophysical information about the site and the starting conditions that describe the soils of the site. | C26: Site.End.S1 | D26: TRUE | E26: TRUE | F26: TRUE | G26: TRUE | K26: No | L26: Season1 End | M26: Character | N26: end date of the first season | P26: lookup_levels$Site.Seasons | Q26: NA | R26: No
A27: Site.Out | B27: Here we record the geographic co-ordinates of where an experiment has taken place and the uncertainty associated with this. You can record multiple locations. For each site you can also capture general biophysical information about the site and the starting conditions that describe the soils of the site. | C27: Site.Length.S1 | D27: TRUE | E27: TRUE | F27: TRUE | G27: TRUE | K27: No | L27: Rainy Season 1 Length (days) | M27: Integer | N27: Length of the first season | P27: NA | Q27: <=365, warning if >=200 and not in RCongo or DRCongo | R27: No
A28: Site.Out | B28: Here we record the geographic co-ordinates of where an experiment has taken place and the uncertainty associated with this. You can record multiple locations. For each site you can also capture general biophysical information about the site and the starting conditions that describe the soils of the site. | C28: Site.Start.S2 | D28: TRUE | E28: TRUE | F28: TRUE | G28: TRUE | K28: No | L28: Season2 Start | M28: Character | N28: start date of the second season | P28: lookup_levels$Site.Seasons | Q28: NA | R28: No
A29: Site.Out | B29: Here we record the geographic co-ordinates of where an experiment has taken place and the uncertainty associated with this. You can record multiple locations. For each site you can also capture general biophysical information about the site and the starting conditions that describe the soils of the site. | C29: Site.End.S2 | D29: TRUE | E29: TRUE | F29: TRUE | G29: TRUE | K29: No | L29: Season2 End | M29: Character | N29: end date of the second season | P29: lookup_levels$Site.Seasons | Q29: NA | R29: No
A30: Site.Out | B30: Here we record the geographic co-ordinates of where an experiment has taken place and the uncertainty associated with this. You can record multiple locations. For each site you can also capture general biophysical information about the site and the starting conditions that describe the soils of the site. | C30: Site.Length.S2 | D30: TRUE | E30: TRUE | F30: TRUE | G30: TRUE | K30: No | L30: Rainy Season 2 Length (days) | M30: Integer | N30: length of the second season | P30: NA | Q30: Value<(365-Site.Length.S1) | R30: No
A31: Site.Out | B31: Here we record the geographic co-ordinates of where an experiment has taken place and the uncertainty associated with this. You can record multiple locations. For each site you can also capture general biophysical information about the site and the starting conditions that describe the soils of the site. | C31: Site.MSP.S1 | D31: TRUE | E31: TRUE | F31: TRUE | G31: TRUE | K31: No | L31: Mean Seasonal Precipitation (mm) - S1 | M31: Integer | N31: Mean Precipitation for the first season | P31: NA | Q31: Range 0 to 9000. Warning on values not in range 200 to 4000. This could be linked to a country table. | R31: No
A32: Site.Out | B32: Here we record the geographic co-ordinates of where an experiment has taken place and the uncertainty associated with this. You can record multiple locations. For each site you can also capture general biophysical information about the site and the starting conditions that describe the soils of the site. | C32: Site.MSP.S2 | D32: TRUE | E32: TRUE | F32: TRUE | G32: TRUE | K32: No | L32: Mean Seasonal Precipitation (mm) - S2 | M32: Integer | N32: Mean Precipitation fot the second season | P32: NA | Q32: Range 0 to 9000. Warning on values not in range 200 to 4000. This could be linked to a country table. | R32: No
A33: Site.Out | B33: Here we record the geographic co-ordinates of where an experiment has taken place and the uncertainty associated with this. You can record multiple locations. For each site you can also capture general biophysical information about the site and the starting conditions that describe the soils of the site. | C33: Site.MAP | D33: TRUE | E33: TRUE | F33: TRUE | G33: TRUE | K33: No | L33: Mean Annual Rainfall (mm) | M33: Integer | N33: This field is used to report the long-term avergae mean annual rainfall of the location. Rainall that is reported for a specific season or year during the experiment should be recorded in the times tab | P33: NA | Q33: Range 0 to 9000. Warning on values not in range 200 to 4000. This could be linked to a country table. | R33: No
A34: Site.Out | B34: Here we record the geographic co-ordinates of where an experiment has taken place and the uncertainty associated with this. You can record multiple locations. For each site you can also capture general biophysical information about the site and the starting conditions that describe the soils of the site. | C34: Site.MAT | D34: TRUE | E34: TRUE | F34: TRUE | G34: TRUE | K34: No | L34: Mean Annual Temperature (°C) | M34: Integer | N34: This field is used to report the long-term avergae mean annual temperature of the location. Temperature that is reported for a specific season or year during the experiment should be recorded in the times tab | P34: NA | Q34: Range 5 to 45. Warning on values not in range 10 to 35. | R34: No
A35: Site.Out | B35: Here we record the geographic co-ordinates of where an experiment has taken place and the uncertainty associated with this. You can record multiple locations. For each site you can also capture general biophysical information about the site and the starting conditions that describe the soils of the site. | C35: Site.Elevation | D35: TRUE | E35: TRUE | F35: TRUE | G35: TRUE | K35: No | L35: Elevation (masl) | M35: Integer | N35: Elevation in meters above sea level | P35: NA | Q35: Range -200 to 5000. Warning on values not in range to 5 to 3500. | R35: No
... A38: Site.Out | B38: Here we record the geographic co-ordinates of where an experiment has taken place and the uncertainty associated with this. You can record multiple locations. For each site you can also capture general biophysical information about the site and the starting conditions that describe the soils of the site. | C38: Site.Soil.Texture | D38: TRUE | E38: TRUE | F38: TRUE | G38: TRUE | K38: No | L38: Soil Texture | M38: Character | N38: Texture of the soil site | P38: lookup_levels$Soil.Texture | Q38: NA | R38: No
A39: Site.Out | B39: Here we record the geographic co-ordinates of where an experiment has taken place and the uncertainty associated with this. You can record multiple locations. For each site you can also capture general biophysical information about the site and the starting conditions that describe the soils of the site. | C39: Site.Notes | D39: TRUE | E39: TRUE | F39: TRUE | G39: TRUE | K39: No | L39: Site.Notes | M39: Character | P39: Free Text | Q39: NA | R39: No
A40: Site.Out | B40: Here we record the geographic co-ordinates of where an experiment has taken place and the uncertainty associated with this. You can record multiple locations. For each site you can also capture general biophysical information about the site and the starting conditions that describe the soils of the site. | C40: B.Code | D40: TRUE | E40: TRUE | F40: TRUE | G40: TRUE | H40: f | I40: Pub.Out | K40: Yes | L40: NA | M40: Character | N40: =N$2 -> A unique code that identifies an extracted publication in the ERA dataset. This code is present in all the tables of era extraction data models. | P40: Pub.Out$B.Code | Q40: NA | R40: NA | S40: NA | T40: NA | U40: NA | V40: NA | W40: NA | Z40: NA | AA40: NA | AB40: NA | AC40: NA | AD40: NA | AE40: NA | AF40: NA
A41: Soil.Out | B41: This section is used to record detailed soil properties at the beginning of an experiment, including texture, pH, nutrient content, and other relevant information. You can add several lines to the table where soil properties are reported for multiple depths. Don't record soil properties measured after an experiment has begun here. | C41: Site.ID | D41: TRUE | E41: TRUE | F41: TRUE | G41: TRUE | H41: f | I41: Site.Out | K41: No | L41: Site Name | M41: Character | N41: If you select a site name that already exists in ERA, the latitude and longitude fields will auto-populate. Please check the auto-generated co-ordinates against the ones reported in the publication and in GoogleMaps/Earth. If there is a mismatch you can overwrite the autogenerated values. | P41: Free Text/Can choose exisiting Site.ID for specified Country within the database or add a new one, perhaps the list should also be subset by Site experimental type. If co-ordinates are changed for the site we need to Flag this to check. | Q41: None | R41: Yes | S41: NA | T41: NA | U41: NA | V41: NA | W41: NA | X41: Camila | Y41: Nombre del sitio
A43: Soil.Out | B43: This section is used to record detailed soil properties at the beginning of an experiment, including texture, pH, nutrient content, and other relevant information. You can add several lines to the table where soil properties are reported for multiple depths. Don't record soil properties measured after an experiment has begun here. | C43: Soil.Upper | D43: TRUE | E43: TRUE | F43: TRUE | G43: TRUE | K43: No | L43: Depth (cm) Upper | M43: Numeric | N43: The upper limit of depth at which soil samples are collected for analysis of soil properties such as texture, pH, and nutrient content. | P43: NA | Q43: Range 0 to 500, Soil.Upper>=Soil.Lower | R43: Yes | S43: AGROVOC | T43: depth | U43: http://aims.fao.org/aos/agrovoc/c_2190 | V43: Partial | W43: measure > dimensions > depth | X43: Camila | Y43: Profundidad
...

Sheet prac
A1: Code | B1: Theme | C1: Theme.Code | D1: Practice | E1: Practice.Code | F1: Subpractice | G1: Subpractice.Code | H1: Subpractice.S | I1: Subpractice.Suffix | J1: Definition | K1: Notes | L1: Linked.Tab | M1: Linked.Col | N1: Depreciated
A2: a1 | B2: Agroforestry | C2: Agroforestry | D2: FMNR | E2: FMNR | F2: Farmer Managed Natural Regeneration | G2: FMNR | H2: FMNR | I2: NA | J2: Systematic regrowth of trees or shrubs on agricultural, forest or pasture land. FMNR is used in areas where there are stumps that can coppice or seeds that can germinate. Sometimes called farmer assisted regeneration. | K2: Typically defined as FMNR or farmer assisted regeneration by author in text. | L2: Int.Out | M2: ED.Int | N2: FALSE
A3: a3 | B3: Agroforestry | C3: Agroforestry | D3: Alleycropping | E3: Al | F3: Alleycropping (N fixing) | G3: Al+N | H3: AgFor Alley (Nfix) | I3: Nfix | J3: Intercropping with rows or alleys of nitrogen fixing trees or woody shrubs. | L3: Int.Out | M3: ED.Int | N3: FALSE
A4: a4 | B4: Agroforestry | C4: Agroforestry | D4: Alleycropping | E4: Al | F4: Alleycropping (Non N fixing) | G4: Al-N | H4: AgFor Alley (nonNfix) | I4: nonNfix | J4: Intercropping with rows or alleys of trees or woody shrubs that do not fix nitrogen. | L4: Int.Out | M4: ED.Int | N4: FALSE
A5: a4.1 | B5: Agroforestry | C5: Agroforestry | D5: Alleycropping | E5: Al | F5: Alleycropping (Mixed) | G5: Al±N | H5: AgFor Alley (Mixed) | I5: Mixed | J5: Intercropping with rows or alleys of a mixture of trees or woody shrubs of which some but not all fix nitrogen. | L5: Int.Out | M5: ED.Int | N5: FALSE
A6: a14 | B6: Agroforestry | C6: Agroforestry | D6: Alleycropping | E6: Al | F6: Alleycropping (Unspecified) | G6: Al | H6: AgFor Alley (noID) | I6: NoID | J6: Intercropping with rows or alleys of trees or woody shrubs where no information about the type of plant is given. | L6: Int.Out | M6: ED.Int | N6: FALSE
A7: a8 | B7: Agroforestry | C7: Agroforestry | D7: Parklands | E7: Pa | F7: Parklands | G7: Pa | H7: Parklands | I7: NA | J7: Intercropping under scattered or regularly planted trees. | K7: Typically named parklands in the document text. Difference with scattered trees is unclear. | L7: Int.Out | M7: ED.Int | N7: FALSE
A8: a8.1 | B8: Agroforestry | C8: Agroforestry | D8: Parklands | E8: Pa | F8: Scattered Trees | G8: ST | H8: Scattered Trees | I8: NA | J8: Unspecified sparse or scattered trees incorporated into croplands, pastures or rangelands. | K8: Difference with Parklands is unclear, other than parklands is not mentioned in the definition. | L8: Int.Out | M8: ED.Int | N8: FALSE
A9: a9 | B9: Agroforestry | C9: Agroforestry | D9: Boundary Planting | E9: BP | F9: Tree Windbreak | G9: TW | H9: Windbreak | I9: NA | J9: Barriers of trees or shrubs planted along field boundaries to protect plants against wind. | L9: AF.Out | M9: AF.Level.Name | N9: FALSE
A10: a10 | B10: Agroforestry | C10: Agroforestry | D10: Boundary Planting | E10: BP | F10: Living Fences or Hedgerows | G10: LF | H10: Hedge | I10: NA | J10: Living fence and hedges are planted in rows around the edge of the field to reduce the effect of wind or runoff on crops. | K10: Note some early agroforestry papers named alleycropping 'hedgerows', but any form of hedge intercropped within a field should be categorized as alleycropping. | L10: AF.Out | M10: AF.Level.Name | N10: FALSE
A11: a11 | B11: Agroforestry | C11: Agroforestry | D11: Silvopasture | E11: Si | F11: Silvopasture | G11: Si | H11: Silvopastoral | I11: NA | J11: Combination of trees or shrubs with pasture (forage grasses) and livestock | L11: AF.Out | M11: AF.Level.Name | N11: FALSE
A12: a22 | B12: Agroforestry | C12: Agroforestry | D12: Silvopasture | E12: Si | F12: Agrosilvopastoral System | G12: AgSi | H12: Agrosilvopastoral | I12: NA | J12: Combination of livestock production systems (pastures) with trees or shrubs and crops. | L12: AF.Out | M12: AF.Level.Name | N12: FALSE
A13: a12 | B13: Agroforestry | C13: Agroforestry | D13: Multistrata Agroforestry | E13: MA | F13: Multistrata Agroforestry | G13: MA | H13: AgFor Multistrata | I13: NA | J13: Multistorey systems agroforestry systems have several spatial strata occupied by different tree (i.e. woody) crops (coffee, tea, cacao, banana etc). | K13: Typically identified as multistrata in the document text. - include two or more vegetation layers and more than one tree species - multiple tree crop species and crops (N-fixing legume cover crops) | L13: Int.Out | M13: ED.Int | N13: FALSE
A14: a15 | B14: Agroforestry | C14: Agroforestry | D14: Agroforestry Pruning | E14: AP | F14: Tree Prunings Applied (Unspecified) | G14: TPA | H14: AgFor Prune (noID) | I14: NoID | J14: Prunings (leaves, branches, etc.) of an unidentified woody plant were retained/returned to the cropping area, but it is unknown if they were mulched or incorporated. | K14: This could be from alleycropping, biomass transfer models or cut-and-carry where prunings come from off the field. It does not include situations where crop processing byproducts such as a oil palm bunch residues or walnut shells are applied to a field, these should be recorded using a regular mulch code. | L14: Res.Out | M14: M.Level.Name | N14: FALSE
A15: a15.1 | B15: Agroforestry | C15: Agroforestry | D15: Agroforestry Pruning | E15: AP | F15: Tree Prunings Mulched (Unspecified) | G15: TPM | H15: AgFor Prune Mulch (noID) | I15: NoID | J15: Prunings (leaves, branches, etc.) of an unidentified woody plant were applied to the cropping area as mulch (prunings on the surface). | K15: This could be from alleycropping, biomass transfer models or cut-and-carry where prunings come from off the field. | L15: Res.Out | M15: M.Level.Name | N15: FALSE
A16: a15.2 | B16: Agroforestry | C16: Agroforestry | D16: Agroforestry Pruning | E16: AP | F16: Tree Prunings Incorporated (Unspecified) | G16: TPI | H16: AgFor Prune Incorp (noID) | I16: NoID | J16: Prunings (leaves, branches, etc.) of an unidentified woody plant were applied to the cropping area and incorporated into the soil (e.g., by ploughing). | K16: This could be from alleycropping, biomass transfer models or cut-and-carry where prunings come from off the field. | L16: Res.Out | M16: M.Level.Name | N16: FALSE
A17: a16 | B17: Agroforestry | C17: Agroforestry | D17: Agroforestry Pruning | E17: AP | F17: Tree Prunings Applied (N fixing) | G17: TAP+N | H17: AgFor Prune (Nfix) | I17: Nfix | J17: Prunings (leaves, branches, etc.) of a nitrogen fixing (leguminous) woody plant residues were retained/returned to the cropping area, but it is unknown if they were mulched or incorporated. | K17: This could be from alleycropping, biomass transfer models or cut-and-carry where prunings come from off the field. | L17: Res.Out | M17: M.Level.Name | N17: FALSE
A18: a16.1 | B18: Agroforestry | C18: Agroforestry | D18: Agroforestry Pruning | E18: AP | F18: Tree Prunings Mulched (N fixing) | G18: TPM+N | H18: AgFor Prune Mulch (Nfix) | I18: Nfix | J18: Prunings (leaves, branches, etc.) of a nitrogen fixing (leguminous) woody plant applied were applied to the cropping area as mulch (prunings on the surface). | K18: This could be from alleycropping, biomass transfer models or cut-and-carry where prunings come from off the field. | L18: Res.Out | M18: M.Level.Name | N18: FALSE
A19: a16.2 | B19: Agroforestry | C19: Agroforestry | D19: Agroforestry Pruning | E19: AP | F19: Tree Prunings Incorporated (N fixing) | G19: TPI+N | H19: AgrFor Prune Incorp (Nfix) | I19: Nfix | J19: Prunings (leaves, branches, etc.) of a nitrogen fixing (leguminous) woody plant applied were applied to the cropping area and incorporated into the soil (e.g., by ploughing). | K19: This could be from alleycropping, biomass transfer models or cut-and-carry where prunings come from off the field. | L19: Res.Out | M19: M.Level.Name | N19: FALSE
A20: a17 | B20: Agroforestry | C20: Agroforestry | D20: Agroforestry Pruning | E20: AP | F20: Tree Prunings Applied (Non N fixing) | G20: TPA-N | H20: AgrFor Prune (nonNfix) | I20: nonNfix | J20: Prunings (leaves, branches, etc.) of a non-nitrogen fixing (not leguminous) woody plant were retained/returned to the cropping area, but it is unknown if they were mulched or incorporated. | K20: This could be from alleycropping, biomass transfer models or cut-and-carry where prunings come from off the field. | L20: Res.Out | M20: M.Level.Name | N20: FALSE
A21: a17.1 | B21: Agroforestry | C21: Agroforestry | D21: Agroforestry Pruning | E21: AP | F21: Tree Prunings Mulched (Non N fixing) | G21: TPM-N | H21: AgFor Prune Mulch (nonNfix) | I21: nonNfix | J21: Prunings (leaves, branches, etc.) of a non-nitrogen fixing (not leguminous) woody plant applied were applied to the cropping area as mulch (prunings on the surface). | K21: This could be from alleycropping, biomass transfer models or cut-and-carry where prunings come from off the field. | L21: Res.Out | M21: M.Level.Name | N21: FALSE
A22: a17.2 | B22: Agroforestry | C22: Agroforestry | D22: Agroforestry Pruning | E22: AP | F22: Tree Prunings Incorporated (Non N fixing) | G22: TPI-N | H22: AgFor Prune Incorp (nonNfix) | I22: nonNfix | J22: Prunings (leaves, branches, etc.) of a non-nitrogen fixing (not leguminous) woody plant applied were applied to the cropping area and incorporated into the soil (e.g., by ploughing). | K22: This could be from alleycropping, biomass transfer models or cut-and-carry where prunings come from off the field. | L22: Res.Out | M22: M.Level.Name | N22: FALSE
A23: a18 | B23: Agroforestry | C23: Agroforestry | D23: Agroforestry Pruning | E23: AP | F23: Tree Pruning (Fate Unknown) | G23: TP | H23: AgFor Prune (Unknown) | I23: Unknown | J23: The cutting or coppicing of woody agroforestry species, generally to reduce competition or shading with intercrops, but the fate of the residues is unknown (it is unclear if was applied or removed). | K23: This could be from alleycropping, biomass transfer models or cut-and-carry where prunings come from off the field. | L23: Res.Out | M23: M.Level.Name | N23: FALSE
A24: a19.1 | B24: Agroforestry | C24: Agroforestry | D24: Agroforestry Fallow | E24: AF | F24: Agroforestry Fallow (N fixing) | G24: AF+N | H24: AgFor Fallow (Nfix) | I24: Nfix | J24: Planting fallows with short-rotation woody or perennial species that fix nitrogen. | L24: Rot.Out | M24: ED.Rot | N24: FALSE
A25: a19.2 | B25: Agroforestry | C25: Agroforestry | D25: Agroforestry Fallow | E25: AF | F25: Agroforestry Fallow (Non N fixing) | G25: AF-N | H25: AgFor Fallow (nonNfix) | I25: nonNfix | J25: Planting fallows with short-rotation woody or perennial species that do not fix nitrogen. | L25: Rot.Out | M25: ED.Rot | N25: FALSE
A26: a19.3 | B26: Agroforestry | C26: Agroforestry | D26: Agroforestry Fallow | E26: AF | F26: Agroforestry Fallow (Unspecified) | G26: AF | H26: AgFor Fallow (NoID) | I26: NoID | J26: Planting fallows with short-rotation woody or perennial species of an unknown type. | L26: Rot.Out | M26: ED.Rot | N26: FALSE
A27: a99 | B27: Agroforestry | C27: Agroforestry | D27: Other Agroforestry | E27: OA | F27: Other Agroforestry | G27: OA | H27: AgFor Other | J27: Agroforestry practice that does not meet definitions in Agroforestry practice theme. | K27: Please notify ERA team if you use this code. | L27: AF.Out | M27: AF.Level.Name | N27: FALSE
A28: d17.1 | B28: Animals | C28: Animals | D28: Feed Addition | E28: FA | F28: Crop Fodders (Added) | G28: FA+CF | H28: Feed Crop (Add) | I28: Add | J28: Feeds added to animal diets that come from non-woody crops not usually grown for fodder, but for another purpose (e.g. consumption). These can be crop grain. field residues (for example maize stalks left over once the grain component has been harvested) and or processing residues (for example the maize bran produced as a byproduct of milling flour). Soyabeans fit in this category as they are grown for human consumption and livestock feed. | K28: Feeds are added compared to a control practice (basal diet) that does not contain items which would gain the same ERA classfication. Control diets are often hay ad libitum or hay ad libitum + maize stover. | L28: Animals.Out | M28: A.Level.Name | N28: FALSE
A29: d17.2 | B29: Animals | C29: Animals | D29: Feed Addition | E29: FA | F29: Non Crop Fodders (Added) | G29: FA+NC | H29: Feed NonCrop (Add) | I29: Add | J29: Feeds added to animal diets that are non-woody crops grown primarily for fodder (e.g., alfafa or clover grown to feed to cattle) or non-woody plants harvested from non-cropped areas (e.g., forage grasses such as napier grass grown to stabilize terraces, cactus harvested from boundary fences, wild growing plants in wayside or fallows, algae, etc.). | K29: Feeds are added compared to a control practice (basal diet) that does not contain items which would gain the same ERA classfication. Control diets are often hay ad libitum or hay ad libitum + maize stover. | L29: Animals.Out | M29: A.Level.Name | N29: FALSE
A30: d17.3 | B30: Animals | C30: Animals | D30: Feed Addition | E30: FA | F30: Agroforestry Fodders (Added) | G30: FA+AF | H30: Feed AgFor (Add) | I30: Add | J30: Feeds added to animal diets that are from agroforestry shrub or tree fodders or other woody plants. | K30: Feeds are added compared to a control practice (basal diet) that does not contain items which would gain the same ERA classfication. Control diets are often hay ad libitum or hay ad libitum + maize stover. | L30: Animals.Out | M30: A.Level.Name | N30: FALSE
A31: d17.4 | B31: Animals | C31: Animals | D31: Feed Addition | E31: FA | F31: Animal Manures (Added) | G31: FA+AM | H31: Feed Manure (Add) | I31: Add | J31: Feeds added to animal diets that are animal manures. | K31: Feeds are added compared to a control practice (basal diet) that does not contain items which would gain the same ERA classfication. Control diets are often hay ad libitum or hay ad libitum + maize stover. | L31: Animals.Out | M31: A.Level.Name | N31: FALSE
A32: d17.5 | B32: Animals | C32: Animals | D32: Feed Addition | E32: FA | F32: Other Feed (Added) | G32: FA+O | H32: Feed Other (Add) | I32: Add | J32: Feeds added to animal diets that are non-plant or non-manure based materials. These typically include materials that are the by-product of animal processing (e.g., bone meal or fish meal). | K32: Feeds are added compared to a control practice (basal diet) that does not contain items which would gain the same ERA classfication. Control diets are often hay ad libitum or hay ad libitum + maize stover. | L32: Animals.Out | M32: A.Level.Name | N32: FALSE
A33: d18.1 | B33: Animals | C33: Animals | D33: Feed Substitution | E33: FS | F33: Crop Fodders (Substituted) | G33: FS+CF | H33: Feed Crop (Sub) | I33: Sub | J33: Components of a basal diet fully or partially substituted for residues from crops not primarily grown for fodder, but for another purpose (e.g. consumption). These can be field residues (for example maize stalks left over once the grain component has been harvested) and or processing residues (for example the maize bran produced as a byproduct of milling flour). | K33: Substitutions are typically defined by the author. Usually they are looking to substitute a conventional (e.g. purchased diet) with cheaper or more sustainable alternatives. | L33: Animals.Out | M33: A.Level.Name | N33: FALSE
A34: d18.2 | B34: Animals | C34: Animals | D34: Feed Substitution | E34: FS | F34: Non Crop Fodders (Substituted) | G34: FS+NC | H34: Feed NonCrop (Sub) | I34: Sub | J34: Components of a basal diet fully or partially substituted for non-woody crops grown primarily for fodder (e.g., alfafa or clover grown to feed to cattle) or non-woody plants harvested from non-cropped areas (e.g., forage grasses such as napier grass grown to stabilize terraces, cactus harvested from boundary fences, wild growing plants in wayside or fallows, algae, etc.). Feeds are added compared to a base practice control such as hay ad libitum only. | K34: Substitutions are typically defined by the author. Usually they are looking to substitute a conventional (e.g. purchased diet) with cheaper or more sustainable alternatives. | L34: Animals.Out | M34: A.Level.Name | N34: FALSE
A35: d18.3 | B35: Animals | C35: Animals | D35: Feed Substitution | E35: FS | F35: Agroforestry Fodders (Substituted) | G35: FS+AF | H35: Feed AgFor (Sub) | I35: Sub | J35: Components of a basal diet fully or partially substituted for agroforestry shrub or tree fodders (woody plants). | K35: Substitutions are typically defined by the author. Usually they are looking to substitute a conventional (e.g. purchased diet) with cheaper or more sustainable alternatives. | L35: Animals.Out | M35: A.Level.Name | N35: FALSE
A36: d18.4 | B36: Animals | C36: Animals | D36: Feed Substitution | E36: FS | F36: Animal Manures (Substituted) | G36: FS+AM | H36: Feed Manure (Sub) | I36: Sub | J36: Components of a basal diet fully or partially substituted for animal manures. | K36: Substitutions are typically defined by the author. Usually they are looking to substitute a conventional (e.g. purchased diet) with cheaper or more sustainable alternatives. | L36: Animals.Out | M36: A.Level.Name | N36: FALSE
A37: d18.5 | B37: Animals | C37: Animals | D37: Feed Substitution | E37: FS | F37: Other Feed (Substituted) | G37: FS+O | H37: Feed Byproducts (Sub) | I37: Sub | J37: Components of a basal diet fully or partially substituted with non-plant and non-manure based materials. These typically include materials for the by-product of animal processing (e.g., bone meal or fish meal). | K37: Substitutions are typically defined by the author. Usually they are looking to substitute a conventional (e.g. purchased diet) with cheaper or more sustainable alternatives. | L37: Animals.Out | M37: A.Level.Name | N37: FALSE
A38: d22.1 | B38: Animals | C38: Animals | D38: Feed Processing | E38: FP | F38: Chemically Processed Feed | G38: FP+Ch | H38: Feed Chem Process | I38: NA | J38: Fodders that have been chemically processed, for example urea-treated stover or fermented fodders. Silage is a type of fodder made from green foliage crops which have been preserved by acidification, achieved through fermentation. | L38: Animals.Out | M38: A.Level.Name | N38: FALSE
A39: d22.2 | B39: Animals | C39: Animals | D39: Feed Processing | E39: FP | F39: Mechanically Processed Feed | G39: FP+Me | H39: Feed Mech Process | I39: NA | J39: Fodders or plant wastes that have been mechanically processed, for example chopped or pelletted grasses or ground orange peel. | L39: Animals.Out | M39: A.Level.Name | N39: FALSE
A40: d22.3 | B40: Animals | C40: Animals | D40: Feed Processing | E40: FP | F40: Concentrated Feed | G40: FP+Co | H40: Feed Concentrates | I40: NA | J40: Non-forage feeds rich in energy and protein. Concentrates include feeds such as maize bran, cotton seed cake, molasses, fish meal and bean cake. Non-forage feeds may use energy or protein rich part plants such as seeds, whereas forage feeds are mainly plant leaves and stems. | L40: Animals.Out | M40: A.Level.Name | N40: FALSE
...

Sheet prod
A1: EU | B1: Product.Type | C1: Product.Type.Code | D1: Product.Subtype | E1: Product.Subtype.Code | F1: Product | G1: Product.Simple | H1: Product.Simple.Code | I1: Component | J1: Latin.Name | K1: Notes | L1: Nfix | M1: Tree | N1: Mulched | O1: Incorp | P1: Unknown.Fate | Q1: ECOCROP.Name | R1: ECOCROP.Notes | S1: ICC_Code_1.1 | T1: ICC_CropName | U1: Livestock_Group | V1: Livestock_Class | W1: Livestock_Descriptor | X1: CPC_Code_2.1 | Y1: WFO_Code | Z1: UN_Comtrade_Code_1 | AA1: UN_Comtrade_Description_1 | AB1: UN_Comtrade_Code_2 | AC1: UN_Comtrade_Description_2 | AD1: MapSPAM
A2: a5 | B2: Animal | C2: Animal | D2: Bovine | E2: Bo | F2: Buffalo | G2: Buffalo | H2: Buf | I2: Meat | J2: Bubalus bubalis | L2: NA | M2: NA | N2: NA | O2: NA | P2: NA | Q2: NA | R2: NA | S2: NA | T2: NA | U2: 1 | V2: 12 | W2: buffaloes | X2: 2112 | Y2: NA | Z2: 201 | AA2: meat of bovine animals; fresh or chilled
A3: a8 | B3: Animal | C3: Animal | D3: Bovine | E3: Bo | F3: Cattle (Meat) | G3: Cattle | H3: Cat | I3: Meat | L3: NA | M3: NA | N3: NA | O3: NA | P3: NA | Q3: NA | R3: NA | S3: NA | T3: NA | U3: 1 | V3: 11 | W3: cattle | X3: 2111 | Y3: NA | Z3: 201 | AA3: meat of bovine animals; fresh or chilled
A4: a8.1 | B4: Animal | C4: Animal | D4: Bovine | E4: Bo | F4: Cattle (Milk) | G4: Cattle | H4: Cat | I4: Milk | L4: NA | M4: NA | N4: NA | O4: NA | P4: NA | Q4: NA | R4: NA | S4: NA | T4: NA | U4: 1 | V4: 11 | W4: cattle | X4: 2111 | Y4: NA | Z4: 401 | AA4: milk and cream; not concentrated, not containing added sugar or other sweetening matter
A5: a6 | B5: Animal | C5: Animal | D5: Camelid | E5: Cam | F5: Camel (Meat) | G5: Camel | H5: Cam | I5: Meat | J5: Camelus dromedarius | L5: NA | M5: NA | N5: NA | O5: NA | P5: NA | Q5: NA | R5: NA | S5: NA | T5: NA | U5: 5 | V5: 51 | W5: camels | X5: 2121 | Y5: NA | Z5: 20860 | AA5: meat and edible meat offal; of camels and other camelids (Camelidae), fresh, chilled or frozen
A6: a6.1 | B6: Animal | C6: Animal | D6: Camelid | E6: Cam | F6: Camel (Milk) | G6: Camel | H6: Cam | I6: Milk | J6: Camelus dromedarius | L6: NA | M6: NA | N6: NA | O6: NA | P6: NA | Q6: NA | R6: NA | S6: NA | T6: NA | U6: 5 | V6: 51 | W6: camels | X6: 2121 | Y6: NA | Z6: 10613 | AA6: mammals; live, camels and other camelids (Camelidae) | AB6: 401 | AC6: milk and cream; not concentrated, not containing added sugar or other sweetening matter
A7: a13 | B7: Animal | C7: Animal | D7: Caprine | E7: Cap | F7: Goat (Meat) | G7: Goat | H7: Goa | I7: Meat | J7: Capra aegagrus hircus | L7: NA | M7: NA | N7: NA | O7: NA | P7: NA | Q7: NA | R7: NA | S7: NA | T7: NA | U7: 2 | V7: 22 | W7: goats | X7: 2123 | Y7: NA | Z7: 20450 | AA7: meat; of goats, fresh, chilled or frozen
A8: a13.1 | B8: Animal | C8: Animal | D8: Caprine | E8: Cap | F8: Goat (Milk) | G8: Goat | H8: Goa | I8: Milk | J8: Capra aegagrus hircus | L8: NA | M8: NA | N8: NA | O8: NA | P8: NA | Q8: NA | R8: NA | S8: NA | T8: NA | U8: 2 | V8: 22 | W8: goats | X8: 2123 | Y8: NA | Z8: 10420 | AA8: Goats; live | AB8: 401 | AC8: milk and cream; not concentrated, not containing added sugar or other sweetening matter
A9: a20 | B9: Animal | C9: Animal | D9: Caprine | E9: Cap | F9: Sheep (Meat) | G9: Sheep | H9: Shee | I9: Meat | J9: Ovis aries | L9: NA | M9: NA | N9: NA | O9: NA | P9: NA | Q9: NA | R9: NA | S9: NA | T9: NA | U9: 2 | V9: 21 | W9: sheep | X9: 2122 | Y9: NA | Z9: 204 | AA9: meat of sheep or goats; fresh, chilled or frozen
A10: a20.1 | B10: Animal | C10: Animal | D10: Caprine | E10: Cap | F10: Sheep (Milk) | G10: Sheep | H10: Shee | I10: Milk | J10: Ovis aries | L10: NA | M10: NA | N10: NA | O10: NA | P10: NA | Q10: NA | R10: NA | S10: NA | T10: NA | U10: 2 | V10: 21 | W10: sheep | X10: 2122 | Y10: NA | Z10: 10410 | AA10: sheep; live | AB10: 401 | AC10: milk and cream; not concentrated, not containing added sugar or other sweetening matter
A11: a20.2 | B11: Animal | C11: Animal | D11: Caprine | E11: Cap | F11: Sheep (Wool) | G11: Sheep | H11: Shee | I11: Wool | J11: Ovis aries | L11: NA | M11: NA | N11: NA | O11: NA | P11: NA | Q11: NA | R11: NA | S11: NA | T11: NA | U11: 2 | V11: 21 | W11: sheep | X11: 2122 | Y11: NA | Z11: 10410 | AA11: sheep; live
A12: n8 | B12: Plant | C12: Plant | D12: Cash Crops | E12: CaCr | F12: Aloe | G12: Aloe | H12: Alo | I12: Leaf | J12: Aloe vera;Aloe sp | L12: No | M12: No | N12: b27.2 | O12: b41.2 | P12: b40.2 | Q12: Aloe sp. | R12: Aloe arborescens + Aloe barbadensis + Aloe ferox + Aloe perryi | S12: no match | T12: no match | U12: NA | V12: NA | W12: NA | X12: NA | Y12: wfo-0000758976-wfo-4000001341 | Z12: no match
A13: l4.1 | B13: Plant | C13: Plant | D13: Cash Crops | E13: CaCr | F13: Coffee Arabica | G13: Arabica | H13: Ara | I13: Seed | J13: Coffea arabica | L13: No | M13: Yes | N13: a17.1 | O13: a17.2 | P13: a17 | Q13: Coffea arabica | S13: 6.01.01 | T13: coffee | U13: NA | V13: NA | W13: NA | X13: NA | Y13: wfo-0000910097 | Z13: 90111 | AA13: coffee; not roasted or decaffeinated | AD13: arabica coffee
A14: l4.2 | B14: Plant | C14: Plant | D14: Cash Crops | E14: CaCr | F14: Coffee Arabica (Pods) | G14: Arabica | H14: Ara | I14: Pods | J14: Coffea arabica | L14: No | M14: Yes | N14: a17.1 | O14: a17.2 | P14: a17 | Q14: Coffea arabica | S14: 6.01.01 | T14: coffee | U14: NA | V14: NA | W14: NA | X14: NA | Y14: wfo-0000910097 | Z14: 90111 | AA14: coffee; not roasted or decaffeinated | AD14: arabica coffee
A15: l18 | B15: Plant | C15: Plant | D15: Cash Crops | E15: CaCr | F15: Chamomile | G15: Chamomile | H15: Camo | I15: Flower | J15: Matricaria chamomilla | L15: No | M15: No | N15: b27.2 | O15: b41.2 | P15: b40.2 | Q15: NA | S15: no match | U15: NA | V15: NA | W15: NA | X15: NA | Y15: NA | Z15: no match
A16: l2 | B16: Plant | C16: Plant | D16: Cash Crops | E16: CaCr | F16: Cocoa or Cacao | G16: Cocoa | H16: Cocoa | I16: Unspecified | J16: Theobroma cacao | K16: Seeds or beans | L16: No | M16: Yes | N16: a17.1 | O16: a17.2 | P16: a17 | Q16: Theobroma cacao | S16: 6.01.04 | T16: cocoa (cacao) | U16: NA | V16: NA | W16: NA | X16: NA | Y16: wfo-0000458440 | Z16: 180100 | AA16: cocoa beans; whole or broken, raw or roasted | AD16: cocoa
A17: l2.1 | B17: Plant | C17: Plant | D17: Cash Crops | E17: CaCr | F17: Cocoa or Cacao (Beans) | G17: Cocoa | H17: Cocoa | I17: Seed | J17: Theobroma cacao | K17: Seeds or beans | L17: No | M17: Yes | N17: a17.1 | O17: a17.2 | P17: a17 | Q17: Theobroma cacao | S17: 6.01.04 | T17: cocoa (cacao) | U17: NA | V17: NA | W17: NA | X17: NA | Y17: wfo-0000458440 | Z17: 180100 | AA17: cocoa beans; whole or broken, raw or roasted | AD17: cocoa
A18: l2.2 | B18: Plant | C18: Plant | D18: Cash Crops | E18: CaCr | F18: Cocoa or Cacao (Butter) | G18: Cocoa | H18: Cocoa | I18: Oil | J18: Theobroma cacao | K18: Cocoa liquor, cocoa butter or chocolate | L18: No | M18: Yes | N18: a17.1 | O18: a17.2 | P18: a17 | Q18: Theobroma cacao | S18: 6.01.04 | T18: cocoa (cacao) | U18: NA | V18: NA | W18: NA | X18: NA | Y18: wfo-0000458440 | Z18: 180400 | AA18: cocoa; butter, fat and oil | AD18: cocoa
A19: l2.3 | B19: Plant | C19: Plant | D19: Cash Crops | E19: CaCr | F19: Cocoa or Cacao (Pods) | G19: Cocoa | H19: Cocoa | I19: Pods | J19: Theobroma cacao | K19: Pods | L19: No | M19: Yes | N19: a17.1 | O19: a17.2 | P19: a17 | Q19: Theobroma cacao | S19: 6.01.04 | T19: cocoa (cacao) | U19: NA | V19: NA | W19: NA | X19: NA | Y19: wfo-0000458440 | Z19: no match | AD19: cocoa
A20: l4 | B20: Plant | C20: Plant | D20: Cash Crops | E20: CaCr | F20: Coffee | G20: Coffee | H20: Cof | I20: Seed | J20: Coffea sp | L20: No | M20: Yes | N20: a17.1 | O20: a17.2 | P20: a17 | Q20: Coffea sp. | S20: 6.01.01 | T20: coffee | U20: NA | V20: NA | W20: NA | X20: NA | Y20: wfo-4000008851 | Z20: 90111 | AA20: coffee; not roasted or decaffeinated
A21: l14 | B21: Plant | C21: Plant | D21: Cash Crops | E21: CaCr | F21: Cupuaçu | G21: Cupuaçu | H21: Cup | I21: Fruit | J21: Theobroma grandiflorum | L21: No | M21: Yes | N21: a17.1 | O21: a17.2 | P21: a17 | Q21: Theobroma grandiflorum | R21: Amazonia species used to make a cocoa like butter | S21: no match | T21: no match | U21: NA | V21: NA | W21: NA | X21: NA | Y21: wfo-0000458603 | Z21: no match
A22: h16 | B22: Plant | C22: Plant | D22: Cash Crops | E22: CaCr | F22: Guar Gum or Cluster Bean | G22: Guar Gum | H22: GuGu | I22: Seeds | J22: Cyamopsis tetragonoloba | L22: No | M22: Yes | N22: a17.1 | O22: a17.2 | P22: a17 | Q22: Cyamopsis tetragonoloba | S22: no match | T22: no match | U22: NA | V22: NA | W22: NA | X22: NA | Y22: wfo-0000189996 | Z22: 130232 | AA22: mucilages and thickeners; whether or not modified, derived from locust beans, locust bean seeds or guar seeds
A23: l17 | B23: Plant | C23: Plant | D23: Cash Crops | E23: CaCr | F23: Gum Arabic | G23: Gum Arabic | H23: Gum | I23: Sap | J23: Acacia senegal (for example) | L23: No | M23: Yes | N23: a17.1 | O23: a17.2 | P23: a17 | Q23: Acacia senegal | S23: no match | T23: no match | U23: NA | V23: NA | W23: NA | X23: NA | Y23: wfo-0000210855 | Z23: 130120 | AA23: gum arabic
